<sdf version='1.6'>
  <world name='default'>
    <model name='ground_plane'>
      <static>1</static>
      <link name='link'>
        <collision name='collision'>
          <geometry>
            <plane>
              <normal>0 0 1</normal>
              <size>100 100</size>
            </plane>
          </geometry>
          <surface>
            <contact>
              <collide_bitmask>65535</collide_bitmask>
              <ode/>
            </contact>
            <friction>
              <ode>
                <mu>100</mu>
                <mu2>50</mu2>
              </ode>
              <torsional>
                <ode/>
              </torsional>
            </friction>
            <bounce/>
          </surface>
          <max_contacts>10</max_contacts>
        </collision>
        <visual name='visual'>
          <cast_shadows>0</cast_shadows>
          <geometry>
            <plane>
              <normal>0 0 1</normal>
              <size>100 100</size>
            </plane>
          </geometry>
          <material>
            <script>
              <uri>file://media/materials/scripts/gazebo.material</uri>
              <name>Gazebo/Grey</name>
            </script>
          </material>
        </visual>
        <self_collide>0</self_collide>
        <enable_wind>0</enable_wind>
        <kinematic>0</kinematic>
      </link>
    </model>
    <gravity>0 0 -9.8</gravity>
    <magnetic_field>6e-06 2.3e-05 -4.2e-05</magnetic_field>
    <atmosphere type='adiabatic'/>
    <physics name='default_physics' default='0' type='ode'>
      <max_step_size>0.001</max_step_size>
      <real_time_factor>1</real_time_factor>
      <real_time_update_rate>1000</real_time_update_rate>
    </physics>
    <scene>
      <ambient>0.4 0.4 0.4 1</ambient>
      <background>0.7 0.7 0.7 1</background>
      <shadows>1</shadows>
    </scene>
    <audio>
      <device>default</device>
    </audio>
    <wind/>
    <spherical_coordinates>
      <surface_model>EARTH_WGS84</surface_model>
      <latitude_deg>0</latitude_deg>
      <longitude_deg>0</longitude_deg>
      <elevation>0</elevation>
      <heading_deg>0</heading_deg>
    </spherical_coordinates>
    <model name='aruco_map'>
      <pose frame=''>-1.14918 1.87406 0.05 0 -0 0</pose>
      <static>1</static>
      <link name='link'>
        <visual name='visual'>
          <geometry>
            <mesh>
              <uri>model://map/meshes/map.dae</uri>
            </mesh>
          </geometry>
        </visual>
        <self_collide>0</self_collide>
        <enable_wind>0</enable_wind>
        <kinematic>0</kinematic>
      </link>
    </model>
    <light name='user_point_light_0' type='point'>
      <pose frame=''>1.25154 3.40382 1 0 -0 0</pose>
      <diffuse>0.5 0.5 0.5 1</diffuse>
      <specular>0.1 0.1 0.1 1</specular>
      <attenuation>
        <range>20</range>
        <constant>0.5</constant>
        <linear>0.01</linear>
        <quadratic>0.001</quadratic>
      </attenuation>
      <cast_shadows>0</cast_shadows>
      <direction>0 0 -1</direction>
    </light>
    <light name='user_directional_light_0' type='directional'>
      <pose frame=''>0.38139 4.93156 1 0 -0 0</pose>
      <diffuse>0.5 0.5 0.5 1</diffuse>
      <specular>0.1 0.1 0.1 1</specular>
      <direction>0.1 0.1 -0.9</direction>
      <attenuation>
        <range>20</range>
        <constant>0.5</constant>
        <linear>0.01</linear>
        <quadratic>0.001</quadratic>
      </attenuation>
      <cast_shadows>1</cast_shadows>
    </light>
    <light name='user_directional_light_1' type='directional'>
      <pose frame=''>-2.51983 7.48431 1 0 -0 0</pose>
      <diffuse>0.5 0.5 0.5 1</diffuse>
      <specular>0.1 0.1 0.1 1</specular>
      <direction>0.1 0.1 -0.9</direction>
      <attenuation>
        <range>20</range>
        <constant>0.5</constant>
        <linear>0.01</linear>
        <quadratic>0.001</quadratic>
      </attenuation>
      <cast_shadows>1</cast_shadows>
    </light>
    <light name='user_point_light_0_clone' type='point'>
      <pose frame=''>2.29011 0.449297 4 0 -0 0</pose>
      <diffuse>1 1 1 1</diffuse>
      <specular>0.0901961 0.0901961 0.0901961 1</specular>
      <direction>0 0 -1</direction>
      <attenuation>
        <range>15</range>
        <constant>0.2</constant>
        <linear>0.01</linear>
        <quadratic>0.001</quadratic>
      </attenuation>
      <cast_shadows>0</cast_shadows>
    </light>
    <state world_name='default'>
      <sim_time>2562 491000000</sim_time>
      <real_time>48 390784391</real_time>
      <wall_time>1582996231 432156949</wall_time>
      <iterations>47895</iterations>
      <model name='aruco_map'>
        <pose frame=''>1.85573 3.73645 0.001926 0 0 -1.56362</pose>
        <scale>1 1 1</scale>
        <link name='link'>
          <pose frame=''>1.85573 3.73645 0.001926 0 0 -1.56362</pose>
          <velocity>0 0 0 0 -0 0</velocity>
          <acceleration>0 0 0 0 -0 0</acceleration>
          <wrench>0 0 0 0 -0 0</wrench>
        </link>
      </model>
      <model name='autonet_v1'>
        <pose frame=''>0.002567 0.000348 0.05 2e-06 4e-06 -4.2e-05</pose>
        <scale>1 1 1</scale>
        <link name='base_link'>
          <pose frame=''>0.002567 0.000348 0.05 2e-06 4e-06 -4.2e-05</pose>
          <velocity>0.000216 5e-05 2.6e-05 3.2e-05 0.000818 0.000122</velocity>
          <acceleration>-0.205523 0.004113 -0.223589 -3.03409 -0.436815 3.11771</acceleration>
          <wrench>-0.102764 0.002056 -0.111797 0 -0 0</wrench>
        </link>
        <link name='link_left_wheel'>
          <pose frame=''>0.002561 -0.159653 0.038 4.1e-05 0.064837 -3.8e-05</pose>
          <velocity>-6.2e-05 6.3e-05 -1.9e-05 -0.001814 -0.00116 0.001354</velocity>
          <acceleration>0.027293 -0.006325 0.039949 0.170226 -0.104376 -2.36093</acceleration>
          <wrench>1.36463 -0.316236 1.99747 0 -0 0</wrench>
        </link>
        <link name='link_right_wheel'>
          <pose frame=''>0.002575 0.160345 0.038001 -5e-05 0.062301 -4.7e-05</pose>
          <velocity>-3.3e-05 2.5e-05 9e-06 -0.000444 -0.000572 -0.000852</velocity>
          <acceleration>0.01983 -0.023436 0.068986 0.613282 -0.22774 2.14553</acceleration>
          <wrench>0.991488 -1.17179 3.44928 0 -0 0</wrench>
        </link>
      </model>
      <model name='ground_plane'>
        <pose frame=''>0 0 0 0 -0 0</pose>
        <scale>1 1 1</scale>
        <link name='link'>
          <pose frame=''>0 0 0 0 -0 0</pose>
          <velocity>0 0 0 0 -0 0</velocity>
          <acceleration>0 0 0 0 -0 0</acceleration>
          <wrench>0 0 0 0 -0 0</wrench>
        </link>
      </model>
      <light name='user_directional_light_0'>
        <pose frame=''>0.38139 4.93156 1 0 -0 0</pose>
      </light>
      <light name='user_directional_light_1'>
        <pose frame=''>-2.51983 7.48431 1 0 -0 0</pose>
      </light>
      <light name='user_point_light_0'>
        <pose frame=''>2 8 4 0 -0 0</pose>
      </light>
      <light name='user_point_light_0_clone'>
        <pose frame=''>2 0 4 0 -0 0</pose>
      </light>
    </state>
    <gui fullscreen='0'>
      <camera name='user_camera'>
        <pose frame=''>-53.0491 -60.8657 57.6568 0 0.609794 0.604188</pose>
        <view_controller>orbit</view_controller>
        <projection_type>perspective</projection_type>
      </camera>
    </gui>
    <model name='autonet_v1'>
      <link name='base_link'>
        <pose frame=''>0 0 0 0 -0 0</pose>
        <inertial>
          <pose frame=''>-0.099998 0 0.050003 0 -0 0</pose>
          <mass>0.50001</mass>
          <inertia>
            <ixx>0.20621</ixx>
            <ixy>0</ixy>
            <ixz>-1.49997e-07</ixz>
            <iyy>0.20621</iyy>
            <iyz>0</iyz>
            <izz>0.206209</izz>
          </inertia>
        </inertial>
        <collision name='base_link_fixed_joint_lump__collision_chassis_collision'>
          <pose frame=''>0 0 0 0 -0 0</pose>
          <geometry>
            <box>
              <size>0.295 0.295 0.05</size>
            </box>
          </geometry>
          <max_contacts>10</max_contacts>
          <surface>
            <contact>
              <ode/>
            </contact>
            <bounce/>
            <friction>
              <torsional>
                <ode/>
              </torsional>
              <ode/>
            </friction>
          </surface>
        </collision>
        <collision name='base_link_fixed_joint_lump__caster_front_collision_collision_1'>
          <pose frame=''>0.05 0 -0.012 3.14159 1.57079 3.14159</pose>
          <geometry>
            <cylinder>
              <length>0.025</length>
              <radius>0.038</radius>
            </cylinder>
          </geometry>
          <max_contacts>10</max_contacts>
          <surface>
            <contact>
              <ode/>
            </contact>
            <bounce/>
            <friction>
              <torsional>
                <ode/>
              </torsional>
              <ode/>
            </friction>
          </surface>
        </collision>
        <collision name='base_link_fixed_joint_lump__caster_back_collision_collision_2'>
          <pose frame=''>-0.25 0 -0.012 3.14159 1.57079 3.14159</pose>
          <geometry>
            <cylinder>
              <length>0.025</length>
              <radius>0.038</radius>
            </cylinder>
          </geometry>
          <max_contacts>10</max_contacts>
          <surface>
            <contact>
              <ode/>
            </contact>
            <bounce/>
            <friction>
              <torsional>
                <ode/>
              </torsional>
              <ode/>
            </friction>
          </surface>
        </collision>
        <collision name='base_link_fixed_joint_lump__camera_link_collision_3'>
          <pose frame=''>0 0 0.2 0 0.2 0</pose>
          <geometry>
            <box>
              <size>0.04 0.04 0.04</size>
            </box>
          </geometry>
          <surface>
            <contact>
              <ode/>
            </contact>
            <friction>
              <ode/>
              <torsional>
                <ode/>
              </torsional>
            </friction>
            <bounce/>
          </surface>
          <max_contacts>10</max_contacts>
        </collision>
        <visual name='base_link_visual'>
          <pose frame=''>-0.1 0 0 0 -0 0</pose>
          <geometry>
            <box>
              <size>0.295 0.295 0.05</size>
            </box>
          </geometry>
        </visual>
        <visual name='base_link_fixed_joint_lump__caster_back_visual_visual_1'>
          <pose frame=''>-0.25 0 -0.012 3.14159 1.57079 3.14159</pose>
          <geometry>
            <cylinder>
              <length>0.025</length>
              <radius>0.038</radius>
            </cylinder>
          </geometry>
        </visual>
        <visual name='base_link_fixed_joint_lump__camera_link_visual_2'>
          <pose frame=''>0 0 0.2 0 0.2 0</pose>
          <geometry>
            <box>
              <size>0.04 0.04 0.04</size>
            </box>
          </geometry>
          <material>
            <script>
              <uri>__default__</uri>
              <name>__default__</name>
            </script>
          </material>
        </visual>
        <gravity>1</gravity>
        <velocity_decay/>
        <sensor name='camera1' type='camera'>
          <update_rate>30</update_rate>
          <camera name='head'>
            <horizontal_fov>1.39626</horizontal_fov>
            <image>
              <width>640</width>
              <height>480</height>
              <format>R8G8B8</format>
            </image>
            <clip>
              <near>0.02</near>
              <far>300</far>
            </clip>
            <noise>
              <type>gaussian</type>
              <mean>0</mean>
              <stddev>0.007</stddev>
            </noise>
          </camera>
          <plugin name='camera_controller' filename='libgazebo_ros_camera.so'>
            <alwaysOn>1</alwaysOn>
            <updateRate>0.0</updateRate>
            <cameraName>camera1</cameraName>
            <imageTopicName>image_raw</imageTopicName>
            <cameraInfoTopicName>camera_info</cameraInfoTopicName>
            <frameName>camera_link</frameName>
            <hackBaseline>0.07</hackBaseline>
            <distortionK1>0.0</distortionK1>
            <distortionK2>0.0</distortionK2>
            <distortionK3>0.0</distortionK3>
            <distortionT1>0.0</distortionT1>
            <distortionT2>0.0</distortionT2>
            <robotNamespace>/</robotNamespace>
          </plugin>
          <pose frame=''>0 0 0.2 0 0.2 0</pose>
        </sensor>
        <self_collide>0</self_collide>
        <enable_wind>0</enable_wind>
        <kinematic>0</kinematic>
      </link>
      <link name='link_left_wheel'>
        <pose frame=''>0 -0.16 -0.012 0 -0 0</pose>
        <inertial>
          <pose frame=''>0 0 0 -0 1.5707 1.5707</pose>
          <mass>50</mass>
          <inertia>
            <ixx>0.000526667</ixx>
            <ixy>0</ixy>
            <ixz>0</ixz>
            <iyy>0.000526667</iyy>
            <iyz>0</iyz>
            <izz>0.001</izz>
          </inertia>
        </inertial>
        <collision name='link_left_wheel_fixed_joint_lump__link_link_left_wheel_wheel_collision_collision'>
          <pose frame=''>0 0 0 3.14159 1.57079 -1.57089</pose>
          <geometry>
            <cylinder>
              <length>0.025</length>
              <radius>0.038</radius>
            </cylinder>
          </geometry>
          <max_contacts>10</max_contacts>
          <surface>
            <contact>
              <ode/>
            </contact>
            <bounce/>
            <friction>
              <torsional>
                <ode/>
              </torsional>
              <ode/>
            </friction>
          </surface>
        </collision>
        <visual name='link_left_wheel_visual_visual'>
          <pose frame=''>0 0 0 3.14159 1.57079 -1.57089</pose>
          <geometry>
            <cylinder>
              <length>0.025</length>
              <radius>0.038</radius>
            </cylinder>
          </geometry>
          <material>
            <script>
              <name>Gazebo/Blue</name>
              <uri>file://media/materials/scripts/gazebo.material</uri>
            </script>
          </material>
        </visual>
        <gravity>1</gravity>
        <velocity_decay/>
        <self_collide>0</self_collide>
        <enable_wind>0</enable_wind>
        <kinematic>0</kinematic>
      </link>
      <joint name='joint_left_wheel' type='revolute'>
        <child>link_left_wheel</child>
        <parent>base_link</parent>
        <axis>
          <xyz>0 1 0</xyz>
          <limit>
            <lower>-1e+16</lower>
            <upper>1e+16</upper>
          </limit>
          <dynamics>
            <spring_reference>0</spring_reference>
            <spring_stiffness>0</spring_stiffness>
          </dynamics>
          <use_parent_model_frame>1</use_parent_model_frame>
        </axis>
      </joint>
      <link name='link_right_wheel'>
        <pose frame=''>0 0.16 -0.012 0 -0 0</pose>
        <inertial>
          <pose frame=''>0 0 0 -0 1.5707 1.5707</pose>
          <mass>50</mass>
          <inertia>
            <ixx>0.000526667</ixx>
            <ixy>0</ixy>
            <ixz>0</ixz>
            <iyy>0.000526667</iyy>
            <iyz>0</iyz>
            <izz>0.001</izz>
          </inertia>
        </inertial>
        <collision name='link_right_wheel_fixed_joint_lump__link_link_right_wheel_wheel_collision_collision'>
          <pose frame=''>0 0 0 3.14159 1.57079 -1.57089</pose>
          <geometry>
            <cylinder>
              <length>0.025</length>
              <radius>0.038</radius>
            </cylinder>
          </geometry>
          <max_contacts>10</max_contacts>
          <surface>
            <contact>
              <ode/>
            </contact>
            <bounce/>
            <friction>
              <torsional>
                <ode/>
              </torsional>
              <ode/>
            </friction>
          </surface>
        </collision>
        <visual name='link_right_wheel_visual_visual'>
          <pose frame=''>0 0 0 3.14159 1.57079 -1.57089</pose>
          <geometry>
            <cylinder>
              <length>0.025</length>
              <radius>0.038</radius>
            </cylinder>
          </geometry>
          <material>
            <script>
              <name>Gazebo/Blue</name>
              <uri>file://media/materials/scripts/gazebo.material</uri>
            </script>
          </material>
        </visual>
        <gravity>1</gravity>
        <velocity_decay/>
        <self_collide>0</self_collide>
        <enable_wind>0</enable_wind>
        <kinematic>0</kinematic>
      </link>
      <joint name='joint_right_wheel' type='revolute'>
        <child>link_right_wheel</child>
        <parent>base_link</parent>
        <axis>
          <xyz>0 1 0</xyz>
          <limit>
            <lower>-1e+16</lower>
            <upper>1e+16</upper>
          </limit>
          <dynamics>
            <spring_reference>0</spring_reference>
            <spring_stiffness>0</spring_stiffness>
          </dynamics>
          <use_parent_model_frame>1</use_parent_model_frame>
        </axis>
      </joint>
      <static>0</static>
      <plugin name='differential_drive_controller' filename='libgazebo_ros_diff_drive.so'>
        <alwaysOn>1</alwaysOn>
        <updateRate>20</updateRate>
        <leftJoint>joint_left_wheel</leftJoint>
        <rightJoint>joint_right_wheel</rightJoint>
        <wheelSeparation>0.32</wheelSeparation>
        <wheelDiameter>0.076</wheelDiameter>
        <torque>20</torque>
        <commandTopic>cmd_vel</commandTopic>
        <odometryTopic>odom</odometryTopic>
        <odometryFrame>odom</odometryFrame>
        <robotBaseFrame>base_link</robotBaseFrame>
        <robotNamespace>/</robotNamespace>
      </plugin>
      <pose frame=''>0 0 0.5 0 -0 0</pose>
    </model>
  </world>
</sdf>
